<?xml version="1.0"?>
<robot name="iggy" xmlns:xacro="http://www.ros.org/wiki/xacro">
  <xacro:property name="M_PI" value="3.1415926535897931" />
<!-- rosrun gazebo_ros spawn_model -urdf -file `rospack find iggy_description`/urdf/iggy2.urdf -z 1 -model iggy1  -->
<!--body -->
    <link name="base_link">
        <visual>
            <geometry>
                <box size="0.92 0.61 0.31"/>
            </geometry>
        </visual>
        <collision>
            <geometry>
                <box size="0.92 0.61 0.31"/>
            </geometry>
        </collision>
        <inertial>
            <mass value="25.0"/>
            <inertia ixx="2.2666833333"  ixy="0"  ixz="0" iyy="5.3094333333" iyz="0" izz="5.3094333333" />
        </inertial>
    </link>
    
    <link name="mast">
        <visual>
            <geometry>
                <box size="0.25 0.25 1.01"/>
            </geometry>
        </visual>
        <collision>
            <geometry>
                <box size="0.25 0.25 1.01"/>
            </geometry>
        </collision>
        <inertial>
            <mass value="1.0"/>
            <inertia ixx="0.0108333333"  ixy="0"  ixz="0" iyy="1.0209333333" iyz="0" izz="1.0209333333" />
        </inertial>
    </link>
    <joint name="mast_to_base_link" type="fixed">
        <parent link="base_link"/>
        <child link="mast"/>
        <origin xyz="0 0 0.65" rpy="0 0 0"/>
    </joint>
    <gazebo reference="mast">
        <material>Gazebo/Orange</material>
    </gazebo>
<!--Wheel Base Back -->
    <link name="back_wheel_base">
        <visual>
            <geometry>
                <box size="0.11 0.45 0.315"/>
            </geometry>
        </visual>
        <collision>
            <geometry>
                <box size="0.11 0.45 0.315"/>
            </geometry>
        </collision>
        <inertial>
            <mass value="25"/>
            <inertia ixx="0.433975" ixy="0.0" ixz="0.0" iyy="0.5211" iyz="0.0" izz="0.1244333333"/>
        </inertial> 
    </link>
    <joint name="back_wheel_base_to_base_link" type="fixed">
        <parent link="base_link"/>
        <child link="back_wheel_base"/>
        <origin xyz="-0.355 0 -0.30" rpy="0 0 0"/>
    </joint>
    <gazebo reference="back_wheel_base">
        <material>Gazebo/Black</material>
    </gazebo>

<!--back left wheels -->
    <link name="blwheel">
        <visual>
            <origin xyz="0 0 0" rpy="1.570796 0 0" />
            <geometry>
                <cylinder length="0.08" radius="0.125"/>
            </geometry>
        </visual>
        <collision>
            <origin xyz="0 0 0" rpy="1.570796 0 0" />
            <geometry>
                <cylinder length="0.08" radius="0.125"/>
            </geometry>
        </collision>
        <inertial>
            <mass value="1"/>
            <inertia ixx="0.00550625" ixy="0.0" ixz="0.0" iyy="0.00550625" iyz="0.0" izz="0.0078125"/>
        </inertial>
    </link>
    <joint name="back_wheel_base_to_blwheel" type="continuous">
        <parent link="back_wheel_base"/>
        <child link="blwheel"/>
        <axis xyz="0 1 0" />
        <origin xyz="0 0.26 -0.15" rpy="0 0 0"/>
    </joint>
    <gazebo reference="blwheel">
        <material>Gazebo/Green</material>
    </gazebo>

<!--back right wheels -->
    <link name="brwheel">
        <visual>
            <origin xyz="0 0 0" rpy="1.570796 0 0" />
            <geometry>
                <cylinder length="0.08" radius="0.125"/>
            </geometry>
        </visual>
        <collision>
            <origin xyz="0 0 0" rpy="1.570796 0 0" />
            <geometry>
                <cylinder length="0.08" radius="0.125"/>
            </geometry>
        </collision>
        <inertial>
            <mass value="1"/>
            <inertia ixx="0.00550625" ixy="0.0" ixz="0.0" iyy="0.00550625" iyz="0.0" izz="0.0078125"/>
        </inertial>
    </link>
    <joint name="back_wheel_base_to_brwheel" type="continuous">
        <parent link="back_wheel_base"/>
        <child link="brwheel"/>
        <axis xyz="0 1 0" />
        <origin xyz="0 -0.26 -0.15" rpy="0 0 0"/>
    </joint>
    <gazebo reference="brwheel">
        <material>Gazebo/Red</material>
    </gazebo>

<!--Wheel Base Front -->
    <link name="front_wheel_base">
        <visual>
            <geometry>
                <box size="0.11 0.60 0.25"/>
            </geometry>
        </visual>
        <collision>
            <geometry>
                <box size="0.11 0.60 0.25"/>
            </geometry>
        </collision>
        <inertial>
            <mass value="25"/>
            <inertia ixx="0.433975" ixy="0.0" ixz="0.0" iyy="0.5211" iyz="0.0" izz="0.1244333333"/>
        </inertial> 
    </link>
    <joint name="front_wheel_base_to_base_link" type="fixed">
        <parent link="base_link"/>
        <child link="front_wheel_base"/>
        <origin xyz="0.38 0 -0.265" rpy="0 0 0"/>
    </joint>
    <gazebo reference="front_wheel_base">
        <material>Gazebo/Turquoise</material>
    </gazebo>
    
<!--Caster Front Left Wheel -->
    <link name="cflwheel">
        <visual>
            <origin rpy="1.57079632679 0 0" xyz="0 0 0"/>
            <geometry>
                <cylinder length="0.04" radius="0.07"/>
            </geometry>      
        </visual>
        <collision>
            <origin rpy="1.57079632679 0 0" xyz="0 0 0"/>
            <geometry>
                <cylinder length="0.04" radius="0.07"/>
            </geometry>
        </collision>
        <inertial>
            <mass value="0.5"/>
            <inertia ixx="0.0008125" ixy="0.0" ixz="0.0" iyy="0.0008125" iyz="0.0" izz="0.001225"/>
        </inertial>
    </link>  
    <joint name="front_left_wheel_joint" type="continuous">
        <parent link="cfl_pivotplate"/>
        <child link="cflwheel"/>
        <origin xyz="-0.03 0 -0.093" rpy="0 0 0"/>
        <axis xyz="0 1 0"/>
    </joint>
    <gazebo reference="cflwheel">
        <material>Gazebo/Blue</material>
    </gazebo>

<!--Caster Front Left Pivot Plate -->
    <link name="cfl_pivotplate">
        <visual>
            <geometry>
                <box size="0.1 0.1 0.05"/>
            </geometry>
        </visual>
        <collision>
            <geometry>
                <box size="0.1 0.1 0.05"/>
            </geometry>
        </collision>
        <inertial>
            <mass value="0.5"/>
            <inertia ixx="0.0104166667" ixy="0.0" ixz="0.0" iyy="0.0029166667" iyz="0.0" izz="0.0029166667"/>
        </inertial>
    </link>
    <joint name="cfl_pivot_joint" type="continuous">
        <parent link="front_wheel_base"/>
        <child link="cfl_pivotplate"/>
        <origin xyz="0 0.21 -0.147" rpy="0 0 0"/>
        <axis rpy="0 0 0" xyz="0 0 1"/>
    </joint>
    <gazebo reference="pivotplate">
        <material>Gazebo/Orange</material>
    </gazebo>

<!--Caster Front Right Wheel -->
    <link name="cfrwheel">
        <visual>
            <origin rpy="1.57079632679 0 0" xyz="0 0 0"/>
            <geometry>
                <cylinder length="0.04" radius="0.07"/>
            </geometry>      
        </visual>
        <collision>
            <origin rpy="1.57079632679 0 0" xyz="0 0 0"/>
            <geometry>
                <cylinder length="0.04" radius="0.07"/>
            </geometry>
        </collision>
        <inertial>
            <mass value="0.5"/>
            <inertia ixx="0.0008125" ixy="0.0" ixz="0.0" iyy="0.0008125" iyz="0.0" izz="0.001225"/>
        </inertial>
    </link>
    <joint name="front_right_wheel_joint" type="continuous">
        <parent link="cfr_pivotplate"/>
        <child link="cfrwheel"/>
        <origin xyz="-0.03 0 -0.0925" rpy="0 0 0"/>
        <axis rpy="0 0 0" xyz="0 1 0"/>
    </joint>
    <gazebo reference="cfrwheel">
        <material>Gazebo/Red</material>
    </gazebo>
<!--Caster Front Left Pivot Plate -->
    <link name="cfr_pivotplate">
        <visual>
            <geometry>
                <box size="0.1 0.1 0.05"/>
            </geometry>
        </visual>
        <collision>
            <geometry>
                <box size="0.1 0.1 0.05"/>
            </geometry>
        </collision>
        <inertial>
            <mass value="0.5"/>
            <inertia ixx="0.0104166667" ixy="0.0" ixz="0.0" iyy="0.0029166667" iyz="0.0" izz="0.0029166667"/>
        </inertial>
    </link>
    <joint name="cfr_pivot_joint" type="continuous">
        <parent link="front_wheel_base"/>
        <child link="cfr_pivotplate"/>
        <origin xyz="0 -0.21 -0.1475" rpy="0 0 0"/>
        <axis rpy="0 0 0" xyz="0 0 1"/>
    </joint>
    <gazebo reference="pivotplate">
        <material>Gazebo/Orange</material>
    </gazebo>
        
<!--Sensors -->    
  <xacro:include filename="depth_camera.urdf.xacro" />

  <xacro:depth_camera>
    <origin xyz="0 0 0" rpy="0 0 0" />
  </xacro:depth_camera>    

    <joint name="base_link_to_camera" type="fixed">
        <parent link="base_link" />
        <child link="camera_center" />
        <origin xyz="0.125 0 1.1" rpy="0 0.785398 0" />
    </joint>
    
  <link name="imu_link">
    <inertial>
      <mass value="0.001"/>
      <origin xyz="0 0 0" rpy="0 0 0"/>
      <inertia ixx="1e-09" ixy="0.0" ixz="0.0" iyy="1e-09" iyz="0.0" izz="1e-09"/>
    </inertial>
  </link>
  <joint name="imu_joint" type="fixed">
    <parent link="base_link" />
    <child link="imu_link" />
  </joint>

  <link name="navsat_link">
    <visual>
      <geometry>
        <cylinder radius="0.026" length="0.016" />
      </geometry>
      <origin xyz="0 0 0.008" />
      <material name="black" />
    </visual>
  </link>
  <joint name="navsat_joint" type="fixed">
    <parent link="base_link" />
    <child link="navsat_link" />
    <origin xyz="-0.180 0.126 0.1815" />
  </joint>
  
  

    <joint name="velodyne_base_mount_joint" type="fixed">
      <origin xyz="0 0 1.15" />
      <parent link="base_link"/>
      <child link="velodyne_base_link"/>
    </joint>

    <link name="velodyne_base_link">
      <inertial>
        <mass value="0.1"/>
        <origin xyz="0 0 0"/>
        <inertia ixx="0.1" ixy="0" ixz="0" iyy="0.1" iyz="0" izz="0.1"/>
      </inertial>
      <visual>
        <geometry>
          <cylinder radius="0.04267" length="0.14424"/>
        </geometry>
      </visual>
      <collision>
        <origin rpy="0 0 0" xyz="0 0 0.07212"/>
        <geometry>
          <cylinder radius="0.04267" length="0.14424"/>
        </geometry>
      </collision>
    </link>

    <joint name="velodyne_base_scan_joint" type="fixed" >
      <origin xyz="0 0 0.09081" rpy="0 0 0" />
      <parent link="velodyne_base_link" />
      <child link="velodyne"/>
    </joint>
        
    <link name="velodyne">
      <inertial>
        <mass value="0.1"/>
        <origin xyz="0 0 0"/>
        <inertia ixx="0.1" ixy="0" ixz="0" iyy="0.1" iyz="0" izz="0.1"/>
      </inertial>
      <visual>
        <origin xyz="0 0 -0.09081" rpy="0 0 0" />
        <geometry>
          <cylinder radius="0.04267" length="0.15"/>
        </geometry>
      </visual>
    </link>  
<!--Plugins -->
    <!-- Gazebo requires the velodyne_gazebo_plugins package -->
    <gazebo reference="velodyne">
      <sensor type="ray" name="velodyne-HDL32E">
        <pose>0 0 0 0 0 0</pose>
        <visualize>false</visualize>
        <update_rate>10</update_rate>
        <ray>
          <scan>
            <horizontal>
              <samples>500</samples> <!-- Change this to 500 if gazebo keeps timing out -->
              <resolution>1</resolution>
              <min_angle>-${M_PI}</min_angle>
              <max_angle> ${M_PI}</max_angle>
            </horizontal>
            <vertical>
              <samples>32</samples>
              <resolution>1</resolution>
              <min_angle>-${10.67*M_PI/180.0}</min_angle> <!-- This is backwards to support gazebo 2 -->
              <max_angle> ${30.67*M_PI/180.0}</max_angle>
            </vertical>
          </scan>
          <range>
            <min>0.055</min>
            <max>140.0</max>
            <resolution>0.001</resolution>
          </range>
          <noise>
            <type>gaussian</type>
            <mean>0.0</mean>
            <stddev>0.0</stddev>
          </noise>
        </ray>
        <plugin name="gazebo_ros_laser_controller" filename="libgazebo_ros_velodyne_laser.so">
          <topicName>/velodyne_points</topicName>
          <frameName>/velodyne</frameName>
          <min_range>0.9</min_range>
          <max_range>130.0</max_range>
          <gaussianNoise>0.008</gaussianNoise>
        </plugin>
      </sensor>
    </gazebo>
    <gazebo>
     <plugin name="differential_drive_controller" filename="libgazebo_ros_diff_drive.so">
          <rosDebugLevel>Debug</rosDebugLevel>
          <publishWheelTF>false</publishWheelTF>
          <robotNamespace>/</robotNamespace>
          <publishTf>1</publishTf>
          <publishWheelJointState>false</publishWheelJointState>
          <alwaysOn>true</alwaysOn>
          <updateRate>100.0</updateRate>
          <rightJoint>back_wheel_base_to_brwheel</rightJoint>
          <leftJoint>back_wheel_base_to_blwheel</leftJoint>
          <wheelSeparation>1.6</wheelSeparation>
          <wheelDiameter>1.6</wheelDiameter>
          <broadcastTF>1</broadcastTF>
          <wheelTorque>30</wheelTorque>
          <wheelAcceleration>1.8</wheelAcceleration>
          <commandTopic>cmd_vel</commandTopic>
          <odometryFrame>odom</odometryFrame> 
          <odometryTopic>odom</odometryTopic> 
          <robotBaseFrame>base_link</robotBaseFrame>
        </plugin>    
    </gazebo> 
    <gazebo>
        <plugin filename="libhector_gazebo_ros_gps.so" name="gps_controller">
            <updateRate>40</updateRate>
            <robotNamespace>/</robotNamespace>
            <bodyName>navsat_link</bodyName>
            <frameId>base_link</frameId>
            <topicName>/cns5000/fix</topicName>
            <velocityTopicName>/cns5000/vel</velocityTopicName>
            <referenceLatitude>42.679239</referenceLatitude>
            <referenceLongitude>-83.195619</referenceLongitude>
            <referenceHeading>90</referenceHeading>
            <referenceAltitude>282</referenceAltitude>
            <!-- <drift>0.0001 0.0001 0.0001</drift> -->
        </plugin>
    </gazebo>
    <gazebo>
        <plugin filename="libhector_gazebo_ros_imu.so" name="imu_controller">
            <robotNamespace>/</robotNamespace>
            <updateRate>50.0</updateRate>
            <bodyName>imu_link</bodyName>
            <topicName>cns5000/imu_data</topicName>
            <accelDrift>0.00015 0.00015 0.00015</accelDrift>
            <accelGaussianNoise>0.005 0.005 0.005</accelGaussianNoise>
            <rateDrift>0.00015 0.00015 0.00015 </rateDrift>
            <rateGaussianNoise>0.005 0.005 0.005 </rateGaussianNoise>
            <headingDrift>0.00015</headingDrift>
            <headingGaussianNoise>0.00015</headingGaussianNoise>
        </plugin>
    </gazebo>
</robot> 
