<?xml version="1.0"?>
<robot xmlns:xacro="http://ros.org/wiki/xacro">

  <xacro:property name="PI" value="3.1415926535897931" />  
  <xacro:property name="wheel_radius" value="0.098" />
  <xacro:property name="wheel_width" value="0.040" />
  <xacro:property name="wheel_mass" value="1.0" />
  
  <material name="dark_grey"><color rgba="0.2 0.2 0.2 1.0" /></material>
  <material name="light_grey"><color rgba="0.4 0.4 0.4 1.0" /></material>
  <material name="yellow"><color rgba="0.8 0.8 0.0 1.0" /></material>
  <material name="black"><color rgba="0.15 0.15 0.15 1.0" /></material>

  <xacro:macro name="${prefix}_wheel" params="prefix *joint_pose">

    <link name="${prefix}_wheel_link">
      <visual>
        <origin xyz="0 0 0" rpy="${PI/2} 0 0"/>
        <geometry>
          <mesh filename="package://iggy_description/meshes/iggy-wheel.stl"/>
        </geometry>
        <material name="black"/>
      </visual>
      <collision>
        <origin xyz="0 0 0" rpy="${PI/2} 0 0"/>
        <geometry>
          <cylinder radius="${wheel_radius}" length="${wheel_width}"/>
        </geometry>
      </collision>
      <xacro:cylinder_inertial radius="${wheel_radius}" length="${wheel_width}" mass="${wheel_mass}"/>
    </link>

    <gazebo reference="${prefix}_wheel_link">
      <material>Gazebo/DarkGrey</material>
    </gazebo>

    <joint name="${prefix}_wheel" type="continuous">
      <parent link="chassis_link"/>
      <child link="${prefix}_wheel_link" />
      <xacro:insert_block name="joint_pose" />
      <axis xyz="0 1 0" />
    </joint>

    <!-- Iggy has only two motors, one per wheel. -->
    <transmission name="${prefix}_wheel_trans">
      <type>transmission_interface/SimpleTransmission</type>
      <joint name="${prefix}_wheel">
        <hardwareInterface>VelocityJointInterface</hardwareInterface>
      </joint>
      <actuator name="${prefix}_actuator">
        <mechanicalReduction>1</mechanicalReduction>
      </actuator>
    </transmission>
  </xacro:macro>

</robot>
